Traceback (most recent call last):
  File "/home/opn/mambaforge/envs/jupyterbook/lib/python3.13/site-packages/jupyter_cache/executors/utils.py", line 58, in single_nb_execution
    executenb(
    ~~~~~~~~~^
        nb,
        ^^^
    ...<4 lines>...
        **kwargs,
        ^^^^^^^^^
    )
    ^
  File "/home/opn/mambaforge/envs/jupyterbook/lib/python3.13/site-packages/nbclient/client.py", line 1319, in execute
    return NotebookClient(nb=nb, resources=resources, km=km, **kwargs).execute()
           ~~~~~~~~~~~~~~~~~~~~~~~~~~~~~~~~~~~~~~~~~~~~~~~~~~~~~~~~~~~~~~~~~~~^^
  File "/home/opn/mambaforge/envs/jupyterbook/lib/python3.13/site-packages/jupyter_core/utils/__init__.py", line 165, in wrapped
    return loop.run_until_complete(inner)
           ~~~~~~~~~~~~~~~~~~~~~~~^^^^^^^
  File "/home/opn/mambaforge/envs/jupyterbook/lib/python3.13/asyncio/base_events.py", line 725, in run_until_complete
    return future.result()
           ~~~~~~~~~~~~~^^
  File "/home/opn/mambaforge/envs/jupyterbook/lib/python3.13/site-packages/nbclient/client.py", line 709, in async_execute
    await self.async_execute_cell(
        cell, index, execution_count=self.code_cells_executed + 1
    )
  File "/home/opn/mambaforge/envs/jupyterbook/lib/python3.13/site-packages/nbclient/client.py", line 1062, in async_execute_cell
    await self._check_raise_for_error(cell, cell_index, exec_reply)
  File "/home/opn/mambaforge/envs/jupyterbook/lib/python3.13/site-packages/nbclient/client.py", line 918, in _check_raise_for_error
    raise CellExecutionError.from_cell_and_msg(cell, exec_reply_content)
nbclient.exceptions.CellExecutionError: An error occurred while executing the following cell:
------------------
# load shapefile

import geopandas as gpd

shp = gpd.read_file("/data/local/shpmetoswilpro/METOS_WILPRO_20231018.shp")
shp
------------------


[31m---------------------------------------------------------------------------[39m
[31mModuleNotFoundError[39m                       Traceback (most recent call last)
[36mCell[39m[36m [39m[32mIn[12][39m[32m, line 3[39m
[32m      1[39m [38;5;66;03m# load shapefile[39;00m
[32m----> [39m[32m3[39m [38;5;28;01mimport[39;00m[38;5;250m [39m[34;01mgeopandas[39;00m[38;5;250m [39m[38;5;28;01mas[39;00m[38;5;250m [39m[34;01mgpd[39;00m
[32m      5[39m shp = gpd.read_file([33m"[39m[33m/data/local/shpmetoswilpro/METOS_WILPRO_20231018.shp[39m[33m"[39m)
[32m      6[39m shp

[31mModuleNotFoundError[39m: No module named 'geopandas'

