Traceback (most recent call last):
  File "/opt/conda/envs/ofs/lib/python3.13/site-packages/jupyter_cache/executors/utils.py", line 58, in single_nb_execution
    executenb(
    ~~~~~~~~~^
        nb,
        ^^^
    ...<4 lines>...
        **kwargs,
        ^^^^^^^^^
    )
    ^
  File "/opt/conda/envs/ofs/lib/python3.13/site-packages/nbclient/client.py", line 1319, in execute
    return NotebookClient(nb=nb, resources=resources, km=km, **kwargs).execute()
           ~~~~~~~~~~~~~~~~~~~~~~~~~~~~~~~~~~~~~~~~~~~~~~~~~~~~~~~~~~~~~~~~~~~^^
  File "/opt/conda/envs/ofs/lib/python3.13/site-packages/jupyter_core/utils/__init__.py", line 165, in wrapped
    return loop.run_until_complete(inner)
           ~~~~~~~~~~~~~~~~~~~~~~~^^^^^^^
  File "/opt/conda/envs/ofs/lib/python3.13/asyncio/base_events.py", line 719, in run_until_complete
    return future.result()
           ~~~~~~~~~~~~~^^
  File "/opt/conda/envs/ofs/lib/python3.13/site-packages/nbclient/client.py", line 709, in async_execute
    await self.async_execute_cell(
        cell, index, execution_count=self.code_cells_executed + 1
    )
  File "/opt/conda/envs/ofs/lib/python3.13/site-packages/nbclient/client.py", line 1062, in async_execute_cell
    await self._check_raise_for_error(cell, cell_index, exec_reply)
  File "/opt/conda/envs/ofs/lib/python3.13/site-packages/nbclient/client.py", line 918, in _check_raise_for_error
    raise CellExecutionError.from_cell_and_msg(cell, exec_reply_content)
nbclient.exceptions.CellExecutionError: An error occurred while executing the following cell:
------------------
import os

# Get current working directory
print(os.getcwd())

# List files in a directory
print(os.listdir())

# Create a directory
os.mkdir("new_directory")

------------------

----- stdout -----
/home/tyo/marinemet-training/1_
['1_0_intro.ipynb', '1_1_1_understanding_python_conda.ipynb', '1_1_2_jupyterlab.ipynb', '1_1_3_python_basic_syntax.ipynb', '1_1_4_python_function_mod_lib.ipynb', '1_2_python_libraries.ipynb', '1_3_data_manipulation.ipynb', '1_4_data_visualization.ipynb', 'Test.csv', '.ipynb_checkpoints', 'new_directory']
------------------

[31m---------------------------------------------------------------------------[39m
[31mFileExistsError[39m                           Traceback (most recent call last)
[36mCell[39m[36m [39m[32mIn[5][39m[32m, line 10[39m
[32m      7[39m [38;5;28mprint[39m(os.listdir())
[32m      9[39m [38;5;66;03m# Create a directory[39;00m
[32m---> [39m[32m10[39m [43mos[49m[43m.[49m[43mmkdir[49m[43m([49m[33;43m"[39;49m[33;43mnew_directory[39;49m[33;43m"[39;49m[43m)[49m

[31mFileExistsError[39m: [Errno 17] File exists: 'new_directory'

