Traceback (most recent call last):
  File "/opt/conda/envs/ofs/lib/python3.13/site-packages/jupyter_cache/executors/utils.py", line 58, in single_nb_execution
    executenb(
    ~~~~~~~~~^
        nb,
        ^^^
    ...<4 lines>...
        **kwargs,
        ^^^^^^^^^
    )
    ^
  File "/opt/conda/envs/ofs/lib/python3.13/site-packages/nbclient/client.py", line 1319, in execute
    return NotebookClient(nb=nb, resources=resources, km=km, **kwargs).execute()
           ~~~~~~~~~~~~~~~~~~~~~~~~~~~~~~~~~~~~~~~~~~~~~~~~~~~~~~~~~~~~~~~~~~~^^
  File "/opt/conda/envs/ofs/lib/python3.13/site-packages/jupyter_core/utils/__init__.py", line 165, in wrapped
    return loop.run_until_complete(inner)
           ~~~~~~~~~~~~~~~~~~~~~~~^^^^^^^
  File "/opt/conda/envs/ofs/lib/python3.13/asyncio/base_events.py", line 719, in run_until_complete
    return future.result()
           ~~~~~~~~~~~~~^^
  File "/opt/conda/envs/ofs/lib/python3.13/site-packages/nbclient/client.py", line 709, in async_execute
    await self.async_execute_cell(
        cell, index, execution_count=self.code_cells_executed + 1
    )
  File "/opt/conda/envs/ofs/lib/python3.13/site-packages/nbclient/client.py", line 1062, in async_execute_cell
    await self._check_raise_for_error(cell, cell_index, exec_reply)
  File "/opt/conda/envs/ofs/lib/python3.13/site-packages/nbclient/client.py", line 918, in _check_raise_for_error
    raise CellExecutionError.from_cell_and_msg(cell, exec_reply_content)
nbclient.exceptions.CellExecutionError: An error occurred while executing the following cell:
------------------
# GROUPBY

dfgrouped = dsetsel.groupby('time.hour')

for key, val in dfgrouped:
    print(key, type(val))
    
dfhourlymean = dfhourly.mean()
dfhourlymean
------------------

----- stdout -----
0 <class 'xarray.core.dataset.Dataset'>
3 <class 'xarray.core.dataset.Dataset'>
6 <class 'xarray.core.dataset.Dataset'>
9 <class 'xarray.core.dataset.Dataset'>
12 <class 'xarray.core.dataset.Dataset'>
15 <class 'xarray.core.dataset.Dataset'>
18 <class 'xarray.core.dataset.Dataset'>
21 <class 'xarray.core.dataset.Dataset'>
------------------

[31m---------------------------------------------------------------------------[39m
[31mNameError[39m                                 Traceback (most recent call last)
[36mCell[39m[36m [39m[32mIn[26][39m[32m, line 8[39m
[32m      5[39m [38;5;28;01mfor[39;00m key, val [38;5;129;01min[39;00m dfgrouped:
[32m      6[39m     [38;5;28mprint[39m(key, [38;5;28mtype[39m(val))
[32m----> [39m[32m8[39m dfhourlymean = [43mdfhourly[49m.mean()
[32m      9[39m dfhourlymean

[31mNameError[39m: name 'dfhourly' is not defined

