Traceback (most recent call last):
  File "/opt/conda/envs/ofs/lib/python3.13/site-packages/jupyter_cache/executors/utils.py", line 58, in single_nb_execution
    executenb(
    ~~~~~~~~~^
        nb,
        ^^^
    ...<4 lines>...
        **kwargs,
        ^^^^^^^^^
    )
    ^
  File "/opt/conda/envs/ofs/lib/python3.13/site-packages/nbclient/client.py", line 1319, in execute
    return NotebookClient(nb=nb, resources=resources, km=km, **kwargs).execute()
           ~~~~~~~~~~~~~~~~~~~~~~~~~~~~~~~~~~~~~~~~~~~~~~~~~~~~~~~~~~~~~~~~~~~^^
  File "/opt/conda/envs/ofs/lib/python3.13/site-packages/jupyter_core/utils/__init__.py", line 165, in wrapped
    return loop.run_until_complete(inner)
           ~~~~~~~~~~~~~~~~~~~~~~~^^^^^^^
  File "/opt/conda/envs/ofs/lib/python3.13/asyncio/base_events.py", line 719, in run_until_complete
    return future.result()
           ~~~~~~~~~~~~~^^
  File "/opt/conda/envs/ofs/lib/python3.13/site-packages/nbclient/client.py", line 709, in async_execute
    await self.async_execute_cell(
        cell, index, execution_count=self.code_cells_executed + 1
    )
  File "/opt/conda/envs/ofs/lib/python3.13/site-packages/nbclient/client.py", line 1062, in async_execute_cell
    await self._check_raise_for_error(cell, cell_index, exec_reply)
  File "/opt/conda/envs/ofs/lib/python3.13/site-packages/nbclient/client.py", line 918, in _check_raise_for_error
    raise CellExecutionError.from_cell_and_msg(cell, exec_reply_content)
nbclient.exceptions.CellExecutionError: An error occurred while executing the following cell:
------------------
for obj in client.list_objects("zarr-data"):
    print(obj.object_name)
------------------


[31m---------------------------------------------------------------------------[39m
[31mNameError[39m                                 Traceback (most recent call last)
[36mCell[39m[36m [39m[32mIn[7][39m[32m, line 1[39m
[32m----> [39m[32m1[39m [38;5;28;01mfor[39;00m obj [38;5;129;01min[39;00m [43mclient[49m.list_objects([33m"[39m[33mzarr-data[39m[33m"[39m):
[32m      2[39m     [38;5;28mprint[39m(obj.object_name)

[31mNameError[39m: name 'client' is not defined

